Workbook

Sheet Class Sum-WR
F1: Applejack Wine & Spirits
F2: Sales/GM$ by Class
F3: Wheat Ridge Retail Store
H5: TY SALES | N5: LAST YEAR CALENDAR | S5: LY DATES | U5: LY SALES | AA5: SALES VARIANCE | AG5: SALES VARIANCE % | AM5: TY GM $ | AS5: LY GM $ | AY5: GM $ VARIANCE | BE5: GM $ VARIANCE % | BK5: TY GM % | BQ5: LY GM % | BW5: GM % VARIANCE | CC5: GM BPS VARIANCE
A6: Fiscal Year | B6: Calendar Year | C6: Fiscal Month | D6: Calendar Month | E6: Fiscal Week | F6: Date | G6: DOW | H6: - None - | I6: Beer | J6: Extras | K6: Spirits | L6: Wine | M6: TY Total Sales | N6: Fiscal Year | O6: Calendar Year | P6: Fiscal Month | Q6: Calendar Month | R6: Fiscal Week | S6: Date | T6: DOW | U6: - None - | V6: Beer | W6: Extras | X6: Spirits | Y6: Wine | Z6: LY Total Sales | AA6: - None - | AB6: Beer | AC6: Extras | AD6: Spirits | AE6: Wine | AF6: Total Variance | AG6: - None - | AH6: Beer | AI6: Extras | AJ6: Spirits | AK6: Wine | AL6: Total Variance | AM6: - None - | AN6: Beer | AO6: Extras | AP6: Spirits | AQ6: Wine | AR6: TY Total GM $ | AS6: - None - | AT6: Beer | AU6: Extras | AV6: Spirits | AW6: Wine | AX6: LY Total GM $ | AY6: - None - | AZ6: Beer | BA6: Extras | BB6: Spirits | BC6: Wine | BD6: Total Variance | BE6: - None - | BF6: Beer | BG6: Extras | BH6: Spirits | BI6: Wine | BJ6: Total Variance | BK6: - None - | BL6: Beer | BM6: Extras | BN6: Spirits | BO6: Wine | BP6: TY Total GM % | BQ6: - None - | BR6: Beer | BS6: Extras | BT6: Spirits | BU6: Wine | BV6: LY Total GM $ | BW6: - None - | BX6: Beer | BY6: Extras | BZ6: Spirits | CA6: Wine | CB6: Total Variance | CC6: - None - | CD6: Beer | CE6: Extras | CF6: Spirits | CG6: Wine | CH6: Total Variance
A7: 0 | B7: FY26 | C7: 0 | D7: 12 Dec | E7: 0 | F7: 46383 | G7: SUN | H7: 0 | I7: 0 | J7: 0 | K7: 0 | L7: 0 | M7: =SUM(H7:L7) -> 0 | N7: 0 | O7: FY25 | P7: 0 | Q7: 12 Dec | R7: Week 00 | S7: 46019 | T7: SUN | U7: -15 | V7: 7488.16 | W7: 517.02 | X7: 39469.81 | Y7: 20861.78 | Z7: =SUM(U7:Y7) -> 68321.77 | AA7: =+H7-U7 -> 15 | AB7: =+I7-V7 -> -7488.16 | AC7: =+J7-W7 -> -517.02 | AD7: =+K7-X7 -> -39469.81 | AE7: =+L7-Y7 -> -20861.78 | AF7: =+M7-Z7 -> -68321.77 | AG7: =AA7/U7 -> -1 | AH7: =AB7/V7 -> -1 | AI7: =AC7/W7 -> -1 | AJ7: =AD7/X7 -> -1 | AK7: =AE7/Y7 -> -1 | AL7: =AF7/Z7 -> -1 | AM7: 0 | AN7: 0 | AO7: 0 | AP7: 0 | AQ7: 0 | AR7: =SUM(AM7:AQ7) -> 0 | AS7: -15 | AT7: 1657.79 | AU7: 221.4 | AV7: 18085.74 | AW7: 6227.25 | AX7: =SUM(AS7:AW7) -> 26177.18 | AY7: =+AM7-AS7 -> 15 | AZ7: =+AN7-AT7 -> -1657.79 | BA7: =+AO7-AU7 -> -221.4 | BB7: =+AP7-AV7 -> -18085.74 | BC7: =+AQ7-AW7 -> -6227.25 | BD7: =+AR7-AX7 -> -26177.18 | BE7: =AY7/AS7 -> -1 | BF7: =AZ7/AT7 -> -1 | BG7: =BA7/AU7 -> -1 | BH7: =BB7/AV7 -> -1 | BI7: =BC7/AW7 -> -1 | BJ7: =BD7/AX7 -> -1 | BK7: =IFERROR(AM7/H7,0) -> 0 | BL7: =IFERROR(AN7/I7,0) -> 0 | BM7: =IFERROR(AO7/J7,0) -> 0 | BN7: =IFERROR(AP7/K7,0) -> 0 | BO7: =IFERROR(AQ7/L7,0) -> 0 | BP7: =IFERROR(AR7/M7,0) -> 0 | BQ7: =IFERROR(AS7/U7,0) -> 1 | BR7: =IFERROR(AT7/V7,0) -> 0.22138816 | BS7: =IFERROR(AU7/W7,0) -> 0.42822328 | BT7: =IFERROR(AV7/X7,0) -> 0.45821705 | BU7: =IFERROR(AW7/Y7,0) -> 0.29850042 | BV7: =IFERROR(AX7/Z7,0) -> 0.38314552 | BW7: =+BK7-BQ7 -> -1 | BX7: =+BL7-BR7 -> -0.22138816 | BY7: =+BM7-BS7 -> -0.42822328 | BZ7: =+BN7-BT7 -> -0.45821705 | CA7: =+BO7-BU7 -> -0.29850042 | CB7: =+BP7-BV7 -> -0.38314552 | CC7: =BW7*10000 -> -10000 | CD7: =BX7*10000 -> -2213.8816 | CE7: =BY7*10000 -> -4282.2328 | CF7: =BZ7*10000 -> -4582.1705 | CG7: =CA7*10000 -> -2985.0042 | CH7: =CB7*10000 -> -3831.4552
A8: 0 | B8: FY26 | C8: 0 | D8: 12 Dec | E8: 0 | F8: =+F7+1 -> 46384 | G8: MON | H8: 0 | I8: 0 | J8: 0 | K8: 0 | L8: 0 | M8: =SUM(H8:L8) -> 0 | N8: 0 | O8: FY25 | P8: 0 | Q8: 12 Dec | R8: Week 00 | S8: =+S7+1 -> 46020 | T8: MON | U8: 84.92 | V8: 12321.39 | W8: 1162.16 | X8: 55070.39 | Y8: 40147.74 | Z8: =SUM(U8:Y8) -> 108786.6 | AA8: =+H8-U8 -> -84.92 | AB8: =+I8-V8 -> -12321.39 | AC8: =+J8-W8 -> -1162.16 | AD8: =+K8-X8 -> -55070.39 | AE8: =+L8-Y8 -> -40147.74 | AF8: =+M8-Z8 -> -108786.6 | AG8: =AA8/U8 -> -1 | AH8: =AB8/V8 -> -1 | AI8: =AC8/W8 -> -1 | AJ8: =AD8/X8 -> -1 | AK8: =AE8/Y8 -> -1 | AL8: =AF8/Z8 -> -1 | AM8: 0 | AN8: 0 | AO8: 0 | AP8: 0 | AQ8: 0 | AR8: =SUM(AM8:AQ8) -> 0 | AS8: 84.92 | AT8: 2598.93 | AU8: 423.44 | AV8: 20633.89 | AW8: 11428.86 | AX8: =SUM(AS8:AW8) -> 35170.04 | AY8: =+AM8-AS8 -> -84.92 | AZ8: =+AN8-AT8 -> -2598.93 | BA8: =+AO8-AU8 -> -423.44 | BB8: =+AP8-AV8 -> -20633.89 | BC8: =+AQ8-AW8 -> -11428.86 | BD8: =+AR8-AX8 -> -35170.04 | BE8: =AY8/AS8 -> -1 | BF8: =AZ8/AT8 -> -1 | BG8: =BA8/AU8 -> -1 | BH8: =BB8/AV8 -> -1 | BI8: =BC8/AW8 -> -1 | BJ8: =BD8/AX8 -> -1 | BK8: =IFERROR(AM8/H8,0) -> 0 | BL8: =IFERROR(AN8/I8,0) -> 0 | BM8: =IFERROR(AO8/J8,0) -> 0 | BN8: =IFERROR(AP8/K8,0) -> 0 | BO8: =IFERROR(AQ8/L8,0) -> 0 | BP8: =IFERROR(AR8/M8,0) -> 0 | BQ8: =IFERROR(AS8/U8,0) -> 1 | BR8: =IFERROR(AT8/V8,0) -> 0.21092831 | BS8: =IFERROR(AU8/W8,0) -> 0.36435603 | BT8: =IFERROR(AV8/X8,0) -> 0.37468211 | BU8: =IFERROR(AW8/Y8,0) -> 0.28467007 | BV8: =IFERROR(AX8/Z8,0) -> 0.32329386 | BW8: =+BK8-BQ8 -> -1 | BX8: =+BL8-BR8 -> -0.21092831 | BY8: =+BM8-BS8 -> -0.36435603 | BZ8: =+BN8-BT8 -> -0.37468211 | CA8: =+BO8-BU8 -> -0.28467007 | CB8: =+BP8-BV8 -> -0.32329386 | CC8: =BW8*10000 -> -10000 | CD8: =BX8*10000 -> -2109.2831 | CE8: =BY8*10000 -> -3643.5603 | CF8: =BZ8*10000 -> -3746.8211 | CG8: =CA8*10000 -> -2846.7007 | CH8: =CB8*10000 -> -3232.9386
A9: 0 | B9: FY26 | C9: 0 | D9: 12 Dec | E9: 0 | F9: =+F8+1 -> 46385 | G9: TUE | H9: 0 | I9: 0 | J9: 0 | K9: 0 | L9: 0 | M9: =SUM(H9:L9) -> 0 | N9: 0 | O9: FY25 | P9: 0 | Q9: 12 Dec | R9: Week 00 | S9: =+S8+1 -> 46021 | T9: TUE | U9: 24.92 | V9: 20806.82 | W9: 1193.52 | X9: 67683.94 | Y9: 72664.98 | Z9: =SUM(U9:Y9) -> 162374.18 | AA9: =+H9-U9 -> -24.92 | AB9: =+I9-V9 -> -20806.82 | AC9: =+J9-W9 -> -1193.52 | AD9: =+K9-X9 -> -67683.94 | AE9: =+L9-Y9 -> -72664.98 | AF9: =+M9-Z9 -> -162374.18 | AG9: =AA9/U9 -> -1 | AH9: =AB9/V9 -> -1 | AI9: =AC9/W9 -> -1 | AJ9: =AD9/X9 -> -1 | AK9: =AE9/Y9 -> -1 | AL9: =AF9/Z9 -> -1 | AM9: 0 | AN9: 0 | AO9: 0 | AP9: 0 | AQ9: 0 | AR9: =SUM(AM9:AQ9) -> 0 | AS9: 24.92 | AT9: 4468.3 | AU9: 279 | AV9: 26740.28 | AW9: 20601.89 | AX9: =SUM(AS9:AW9) -> 52114.39 | AY9: =+AM9-AS9 -> -24.92 | AZ9: =+AN9-AT9 -> -4468.3 | BA9: =+AO9-AU9 -> -279 | BB9: =+AP9-AV9 -> -26740.28 | BC9: =+AQ9-AW9 -> -20601.89 | BD9: =+AR9-AX9 -> -52114.39 | BE9: =AY9/AS9 -> -1 | BF9: =AZ9/AT9 -> -1 | BG9: =BA9/AU9 -> -1 | BH9: =BB9/AV9 -> -1 | BI9: =BC9/AW9 -> -1 | BJ9: =BD9/AX9 -> -1 | BK9: =IFERROR(AM9/H9,0) -> 0 | BL9: =IFERROR(AN9/I9,0) -> 0 | BM9: =IFERROR(AO9/J9,0) -> 0 | BN9: =IFERROR(AP9/K9,0) -> 0 | BO9: =IFERROR(AQ9/L9,0) -> 0 | BP9: =IFERROR(AR9/M9,0) -> 0 | BQ9: =IFERROR(AS9/U9,0) -> 1 | BR9: =IFERROR(AT9/V9,0) -> 0.2147517 | BS9: =IFERROR(AU9/W9,0) -> 0.23376232 | BT9: =IFERROR(AV9/X9,0) -> 0.3950757 | BU9: =IFERROR(AW9/Y9,0) -> 0.28351883 | BV9: =IFERROR(AX9/Z9,0) -> 0.32095244 | BW9: =+BK9-BQ9 -> -1 | BX9: =+BL9-BR9 -> -0.2147517 | BY9: =+BM9-BS9 -> -0.23376232 | BZ9: =+BN9-BT9 -> -0.3950757 | CA9: =+BO9-BU9 -> -0.28351883 | CB9: =+BP9-BV9 -> -0.32095244 | CC9: =BW9*10000 -> -10000 | CD9: =BX9*10000 -> -2147.517 | CE9: =BY9*10000 -> -2337.6232 | CF9: =BZ9*10000 -> -3950.757 | CG9: =CA9*10000 -> -2835.1883 | CH9: =CB9*10000 -> -3209.5244
A10: 0 | B10: FY26 | C10: 0 | D10: 12 Dec | E10: 0 | F10: =+F9+1 -> 46386 | G10: WED | H10: 0 | I10: 0 | J10: 0 | K10: 0 | L10: 0 | M10: =SUM(H10:L10) -> 0 | N10: 0 | O10: FY25 | P10: 0 | Q10: 12 Dec | R10: 0 | S10: =+S9+1 -> 46022 | T10: WED | U10: 124.9 | V10: 31238.55 | W10: 3633.92 | X10: 105816.8 | Y10: 86023.38 | Z10: =SUM(U10:Y10) -> 226837.55 | AA10: =+H10-U10 -> -124.9 | AB10: =+I10-V10 -> -31238.55 | AC10: =+J10-W10 -> -3633.92 | AD10: =+K10-X10 -> -105816.8 | AE10: =+L10-Y10 -> -86023.38 | AF10: =+M10-Z10 -> -226837.55 | AG10: =AA10/U10 -> -1 | AH10: =AB10/V10 -> -1 | AI10: =AC10/W10 -> -1 | AJ10: =AD10/X10 -> -1 | AK10: =AE10/Y10 -> -1 | AL10: =AF10/Z10 -> -1 | AM10: 0 | AN10: 0 | AO10: 0 | AP10: 0 | AQ10: 0 | AR10: =SUM(AM10:AQ10) -> 0 | AS10: 124.9 | AT10: 6802.78 | AU10: 1558.17 | AV10: 38677.41 | AW10: 23133.82 | AX10: =SUM(AS10:AW10) -> 70297.08 | AY10: =+AM10-AS10 -> -124.9 | AZ10: =+AN10-AT10 -> -6802.78 | BA10: =+AO10-AU10 -> -1558.17 | BB10: =+AP10-AV10 -> -38677.41 | BC10: =+AQ10-AW10 -> -23133.82 | BD10: =+AR10-AX10 -> -70297.08 | BE10: =AY10/AS10 -> -1 | BF10: =AZ10/AT10 -> -1 | BG10: =BA10/AU10 -> -1 | BH10: =BB10/AV10 -> -1 | BI10: =BC10/AW10 -> -1 | BJ10: =BD10/AX10 -> -1 | BK10: =IFERROR(AM10/H10,0) -> 0 | BL10: =IFERROR(AN10/I10,0) -> 0 | BM10: =IFERROR(AO10/J10,0) -> 0 | BN10: =IFERROR(AP10/K10,0) -> 0 | BO10: =IFERROR(AQ10/L10,0) -> 0 | BP10: =IFERROR(AR10/M10,0) -> 0 | BQ10: =IFERROR(AS10/U10,0) -> 1 | BR10: =IFERROR(AT10/V10,0) -> 0.21776875 | BS10: =IFERROR(AU10/W10,0) -> 0.42878489 | BT10: =IFERROR(AV10/X10,0) -> 0.36551294 | BU10: =IFERROR(AW10/Y10,0) -> 0.2689248 | BV10: =IFERROR(AX10/Z10,0) -> 0.30990054 | BW10: =+BK10-BQ10 -> -1 | BX10: =+BL10-BR10 -> -0.21776875 | BY10: =+BM10-BS10 -> -0.42878489 | BZ10: =+BN10-BT10 -> -0.36551294 | CA10: =+BO10-BU10 -> -0.2689248 | CB10: =+BP10-BV10 -> -0.30990054 | CC10: =BW10*10000 -> -10000 | CD10: =BX10*10000 -> -2177.6875 | CE10: =BY10*10000 -> -4287.8489 | CF10: =BZ10*10000 -> -3655.1294 | CG10: =CA10*10000 -> -2689.248 | CH10: =CB10*10000 -> -3099.0054
A11: 0 | B11: FY26 | C11: 0 | D11: 12 Dec | E11: 0 | F11: =+F10+1 -> 46387 | G11: THU | H11: 0 | I11: 0 | J11: 0 | K11: 0 | L11: 0 | M11: =SUM(H11:L11) -> 0 | N11: #N/A | O11: #N/A | P11: #N/A | Q11: #N/A | R11: #N/A | S11: =+S12-1 -> 45652 | T11: THU | U11: 0 | V11: 0 | W11: 0 | X11: 0 | Y11: 0 | Z11: =SUM(U11:Y11) -> 0 | AA11: =+H11-U11 -> 0 | AB11: =+I11-V11 -> 0 | AC11: =+J11-W11 -> 0 | AD11: =+K11-X11 -> 0 | AE11: =+L11-Y11 -> 0 | AF11: =+M11-Z11 -> 0 | AG11: =AA11/U11 -> #DIV/0! | AH11: =AB11/V11 -> #DIV/0! | AI11: =AC11/W11 -> #DIV/0! | AJ11: =AD11/X11 -> #DIV/0! | AK11: =AE11/Y11 -> #DIV/0! | AL11: =AF11/Z11 -> #DIV/0! | AM11: 0 | AN11: 0 | AO11: 0 | AP11: 0 | AQ11: 0 | AR11: =SUM(AM11:AQ11) -> 0 | AS11: 0 | AT11: 0 | AU11: 0 | AV11: 0 | AW11: 0 | AX11: =SUM(AS11:AW11) -> 0 | AY11: =+AM11-AS11 -> 0 | AZ11: =+AN11-AT11 -> 0 | BA11: =+AO11-AU11 -> 0 | BB11: =+AP11-AV11 -> 0 | BC11: =+AQ11-AW11 -> 0 | BD11: =+AR11-AX11 -> 0 | BE11: =AY11/AS11 -> #DIV/0! | BF11: =AZ11/AT11 -> #DIV/0! | BG11: =BA11/AU11 -> #DIV/0! | BH11: =BB11/AV11 -> #DIV/0! | BI11: =BC11/AW11 -> #DIV/0! | BJ11: =BD11/AX11 -> #DIV/0! | BK11: =IFERROR(AM11/H11,0) -> 0 | BL11: =IFERROR(AN11/I11,0) -> 0 | BM11: =IFERROR(AO11/J11,0) -> 0 | BN11: =IFERROR(AP11/K11,0) -> 0 | BO11: =IFERROR(AQ11/L11,0) -> 0 | BP11: =IFERROR(AR11/M11,0) -> 0 | BQ11: =IFERROR(AS11/U11,0) -> 0 | BR11: =IFERROR(AT11/V11,0) -> 0 | BS11: =IFERROR(AU11/W11,0) -> 0 | BT11: =IFERROR(AV11/X11,0) -> 0 | BU11: =IFERROR(AW11/Y11,0) -> 0 | BV11: =IFERROR(AX11/Z11,0) -> 0 | BW11: =+BK11-BQ11 -> 0 | BX11: =+BL11-BR11 -> 0 | BY11: =+BM11-BS11 -> 0 | BZ11: =+BN11-BT11 -> 0 | CA11: =+BO11-BU11 -> 0 | CB11: =+BP11-BV11 -> 0 | CC11: =BW11*10000 -> 0 | CD11: =BX11*10000 -> 0 | CE11: =BY11*10000 -> 0 | CF11: =BZ11*10000 -> 0 | CG11: =CA11*10000 -> 0 | CH11: =CB11*10000 -> 0
A12: #N/A | B12: #N/A | C12: #N/A | D12: #N/A | E12: #N/A | F12: =+F13-1 -> 46017 | G12: FRI | H12: -35.05 | I12: 13931.43 | J12: 1254.55 | K12: 47328.16 | L12: 36455.23 | M12: =SUM(H12:L12) -> 98934.32 | N12: #N/A | O12: #N/A | P12: #N/A | Q12: #N/A | R12: #N/A | S12: =+S13-1 -> 45653 | T12: FRI | U12: 0 | V12: 0 | W12: 0 | X12: 0 | Y12: 0 | Z12: =SUM(U12:Y12) -> 0 | AA12: =+H12-U12 -> -35.05 | AB12: =+I12-V12 -> 13931.43 | AC12: =+J12-W12 -> 1254.55 | AD12: =+K12-X12 -> 47328.16 | AE12: =+L12-Y12 -> 36455.23 | AF12: =+M12-Z12 -> 98934.32 | AG12: =AA12/U12 -> #DIV/0! | AH12: =AB12/V12 -> #DIV/0! | AI12: =AC12/W12 -> #DIV/0! | AJ12: =AD12/X12 -> #DIV/0! | AK12: =AE12/Y12 -> #DIV/0! | AL12: =AF12/Z12 -> #DIV/0! | AM12: -35.05 | AN12: 2981.96 | AO12: 503.04 | AP12: 17680.21 | AQ12: 11038.12 | AR12: =SUM(AM12:AQ12) -> 32168.28 | AS12: 0 | AT12: 0 | AU12: 0 | AV12: 0 | AW12: 0 | AX12: =SUM(AS12:AW12) -> 0 | AY12: =+AM12-AS12 -> -35.05 | AZ12: =+AN12-AT12 -> 2981.96 | BA12: =+AO12-AU12 -> 503.04 | BB12: =+AP12-AV12 -> 17680.21 | BC12: =+AQ12-AW12 -> 11038.12 | BD12: =+AR12-AX12 -> 32168.28 | BE12: =AY12/AS12 -> #DIV/0! | BF12: =AZ12/AT12 -> #DIV/0! | BG12: =BA12/AU12 -> #DIV/0! | BH12: =BB12/AV12 -> #DIV/0! | BI12: =BC12/AW12 -> #DIV/0! | BJ12: =BD12/AX12 -> #DIV/0! | BK12: =IFERROR(AM12/H12,0) -> 1 | BL12: =IFERROR(AN12/I12,0) -> 0.21404551 | BM12: =IFERROR(AO12/J12,0) -> 0.40097246 | BN12: =IFERROR(AP12/K12,0) -> 0.37356639 | BO12: =IFERROR(AQ12/L12,0) -> 0.30278564 | BP12: =IFERROR(AR12/M12,0) -> 0.32514784 | BQ12: =IFERROR(AS12/U12,0) -> 0 | BR12: =IFERROR(AT12/V12,0) -> 0 | BS12: =IFERROR(AU12/W12,0) -> 0 | BT12: =IFERROR(AV12/X12,0) -> 0 | BU12: =IFERROR(AW12/Y12,0) -> 0 | BV12: =IFERROR(AX12/Z12,0) -> 0 | BW12: =+BK12-BQ12 -> 1 | BX12: =+BL12-BR12 -> 0.21404551 | BY12: =+BM12-BS12 -> 0.40097246 | BZ12: =+BN12-BT12 -> 0.37356639 | CA12: =+BO12-BU12 -> 0.30278564 | CB12: =+BP12-BV12 -> 0.32514784 | CC12: =BW12*10000 -> 10000 | CD12: =BX12*10000 -> 2140.4551 | CE12: =BY12*10000 -> 4009.7246 | CF12: =BZ12*10000 -> 3735.6639 | CG12: =CA12*10000 -> 3027.8564 | CH12: =CB12*10000 -> 3251.4784
A13: #N/A | B13: #N/A | C13: #N/A | D13: #N/A | E13: #N/A | F13: =+F14-1 -> 46018 | G13: SAT | H13: 104.94 | I13: 14188 | J13: 881.04 | K13: 53531.92 | L13: 42451.05 | M13: =SUM(H13:L13) -> 111156.95 | N13: #N/A | O13: #N/A | P13: #N/A | Q13: #N/A | R13: #N/A | S13: =+S14-1 -> 45654 | T13: SAT | U13: 0 | V13: 0 | W13: 0 | X13: 0 | Y13: 0 | Z13: =SUM(U13:Y13) -> 0 | AA13: =+H13-U13 -> 104.94 | AB13: =+I13-V13 -> 14188 | AC13: =+J13-W13 -> 881.04 | AD13: =+K13-X13 -> 53531.92 | AE13: =+L13-Y13 -> 42451.05 | AF13: =+M13-Z13 -> 111156.95 | AG13: =AA13/U13 -> #DIV/0! | AH13: =AB13/V13 -> #DIV/0! | AI13: =AC13/W13 -> #DIV/0! | AJ13: =AD13/X13 -> #DIV/0! | AK13: =AE13/Y13 -> #DIV/0! | AL13: =AF13/Z13 -> #DIV/0! | AM13: 104.94 | AN13: 3045.13 | AO13: 271.7 | AP13: 20911.64 | AQ13: 12838.41 | AR13: =SUM(AM13:AQ13) -> 37171.82 | AS13: 0 | AT13: 0 | AU13: 0 | AV13: 0 | AW13: 0 | AX13: =SUM(AS13:AW13) -> 0 | AY13: =+AM13-AS13 -> 104.94 | AZ13: =+AN13-AT13 -> 3045.13 | BA13: =+AO13-AU13 -> 271.7 | BB13: =+AP13-AV13 -> 20911.64 | BC13: =+AQ13-AW13 -> 12838.41 | BD13: =+AR13-AX13 -> 37171.82 | BE13: =AY13/AS13 -> #DIV/0! | BF13: =AZ13/AT13 -> #DIV/0! | BG13: =BA13/AU13 -> #DIV/0! | BH13: =BB13/AV13 -> #DIV/0! | BI13: =BC13/AW13 -> #DIV/0! | BJ13: =BD13/AX13 -> #DIV/0! | BK13: =IFERROR(AM13/H13,0) -> 1 | BL13: =IFERROR(AN13/I13,0) -> 0.21462715 | BM13: =IFERROR(AO13/J13,0) -> 0.30838554 | BN13: =IFERROR(AP13/K13,0) -> 0.39063871 | BO13: =IFERROR(AQ13/L13,0) -> 0.30242856 | BP13: =IFERROR(AR13/M13,0) -> 0.33440842 | BQ13: =IFERROR(AS13/U13,0) -> 0 | BR13: =IFERROR(AT13/V13,0) -> 0 | BS13: =IFERROR(AU13/W13,0) -> 0 | BT13: =IFERROR(AV13/X13,0) -> 0 | BU13: =IFERROR(AW13/Y13,0) -> 0 | BV13: =IFERROR(AX13/Z13,0) -> 0 | BW13: =+BK13-BQ13 -> 1 | BX13: =+BL13-BR13 -> 0.21462715 | BY13: =+BM13-BS13 -> 0.30838554 | BZ13: =+BN13-BT13 -> 0.39063871 | CA13: =+BO13-BU13 -> 0.30242856 | CB13: =+BP13-BV13 -> 0.33440842 | CC13: =BW13*10000 -> 10000 | CD13: =BX13*10000 -> 2146.2715 | CE13: =BY13*10000 -> 3083.8554 | CF13: =BZ13*10000 -> 3906.3871 | CG13: =CA13*10000 -> 3024.2856 | CH13: =CB13*10000 -> 3344.0842
A14: FY26 | B14: FY25 | C14: 01 Jan | D14: 0 | E14: Week 01 | F14: 46019 | G14: SUN | H14: -15 | I14: 7488.16 | J14: 517.02 | K14: 39469.81 | L14: 20861.78 | M14: =SUM(H14:L14) -> 68321.77 | N14: FY25 | O14: FY24 | P14: 01 Jan | Q14: 0 | R14: Week 01 | S14: 45655 | T14: SUN | U14: -10.01 | V14: 10565.35 | W14: 621.62 | X14: 35991.4 | Y14: 27095.92 | Z14: =SUM(U14:Y14) -> 74264.28 | AA14: =+H14-U14 -> -4.99 | AB14: =+I14-V14 -> -3077.19 | AC14: =+J14-W14 -> -104.6 | AD14: =+K14-X14 -> 3478.41 | AE14: =+L14-Y14 -> -6234.14 | AF14: =+M14-Z14 -> -5942.51 | AG14: =AA14/U14 -> 0.4985015 | AH14: =AB14/V14 -> -0.29125301 | AI14: =AC14/W14 -> -0.16827 | AJ14: =AD14/X14 -> 0.096645588 | AK14: =AE14/Y14 -> -0.23007671 | AL14: =AF14/Z14 -> -0.080018415 | AM14: -15 | AN14: 1657.79 | AO14: 221.4 | AP14: 18085.74 | AQ14: 6227.25 | AR14: =SUM(AM14:AQ14) -> 26177.18 | AS14: -10.01 | AT14: 2264.47 | AU14: 263.06 | AV14: 10313.99 | AW14: 7511.86 | AX14: =SUM(AS14:AW14) -> 20343.37 | AY14: =+AM14-AS14 -> -4.99 | AZ14: =+AN14-AT14 -> -606.68 | BA14: =+AO14-AU14 -> -41.66 | BB14: =+AP14-AV14 -> 7771.75 | BC14: =+AQ14-AW14 -> -1284.61 | BD14: =+AR14-AX14 -> 5833.81 | BE14: =AY14/AS14 -> 0.4985015 | BF14: =AZ14/AT14 -> -0.26791258 | BG14: =BA14/AU14 -> -0.15836691 | BH14: =BB14/AV14 -> 0.75351537 | BI14: =BC14/AW14 -> -0.17101091 | BJ14: =BD14/AX14 -> 0.28676714 | BK14: =IFERROR(AM14/H14,0) -> 1 | BL14: =IFERROR(AN14/I14,0) -> 0.22138816 | BM14: =IFERROR(AO14/J14,0) -> 0.42822328 | BN14: =IFERROR(AP14/K14,0) -> 0.45821705 | BO14: =IFERROR(AQ14/L14,0) -> 0.29850042 | BP14: =IFERROR(AR14/M14,0) -> 0.38314552 | BQ14: =IFERROR(AS14/U14,0) -> 1 | BR14: =IFERROR(AT14/V14,0) -> 0.21432986 | BS14: =IFERROR(AU14/W14,0) -> 0.42318458 | BT14: =IFERROR(AV14/X14,0) -> 0.28656818 | BU14: =IFERROR(AW14/Y14,0) -> 0.27723214 | BV14: =IFERROR(AX14/Z14,0) -> 0.2739321 | BW14: =+BK14-BQ14 -> 0 | BX14: =+BL14-BR14 -> 0.0070583035 | BY14: =+BM14-BS14 -> 0.0050386973 | BZ14: =+BN14-BT14 -> 0.17164887 | CA14: =+BO14-BU14 -> 0.021268271 | CB14: =+BP14-BV14 -> 0.10921342 | CC14: =BW14*10000 -> 0 | CD14: =BX14*10000 -> 70.583035 | CE14: =BY14*10000 -> 50.386973 | CF14: =BZ14*10000 -> 1716.4887 | CG14: =CA14*10000 -> 212.68271 | CH14: =CB14*10000 -> 1092.1342
A15: FY26 | B15: FY25 | C15: 01 Jan | D15: 0 | E15: Week 01 | F15: =+F14+1 -> 46020 | G15: MON | H15: 84.92 | I15: 12321.39 | J15: 1162.16 | K15: 55070.39 | L15: 40147.74 | M15: =SUM(H15:L15) -> 108786.6 | N15: FY25 | O15: FY24 | P15: 01 Jan | Q15: 0 | R15: Week 01 | S15: =+S14+1 -> 45656 | T15: MON | U15: 74.94 | V15: 15695.19 | W15: 1869.36 | X15: 50000.19 | Y15: 54694.22 | Z15: =SUM(U15:Y15) -> 122333.9 | AA15: =+H15-U15 -> 9.98 | AB15: =+I15-V15 -> -3373.8 | AC15: =+J15-W15 -> -707.2 | AD15: =+K15-X15 -> 5070.2 | AE15: =+L15-Y15 -> -14546.48 | AF15: =+M15-Z15 -> -13547.3 | AG15: =AA15/U15 -> 0.13317321 | AH15: =AB15/V15 -> -0.21495758 | AI15: =AC15/W15 -> -0.37831129 | AJ15: =AD15/X15 -> 0.10140361 | AK15: =AE15/Y15 -> -0.2659601 | AL15: =AF15/Z15 -> -0.11074036 | AM15: 84.92 | AN15: 2598.93 | AO15: 423.44 | AP15: 20633.89 | AQ15: 11428.86 | AR15: =SUM(AM15:AQ15) -> 35170.04 | AS15: 74.94 | AT15: 3259.25 | AU15: 953.98 | AV15: 15187.72 | AW15: 14658.12 | AX15: =SUM(AS15:AW15) -> 34134.01 | AY15: =+AM15-AS15 -> 9.98 | AZ15: =+AN15-AT15 -> -660.32 | BA15: =+AO15-AU15 -> -530.54 | BB15: =+AP15-AV15 -> 5446.17 | BC15: =+AQ15-AW15 -> -3229.26 | BD15: =+AR15-AX15 -> 1036.03 | BE15: =AY15/AS15 -> 0.13317321 | BF15: =AZ15/AT15 -> -0.20259876 | BG15: =BA15/AU15 -> -0.55613325 | BH15: =BB15/AV15 -> 0.35859036 | BI15: =BC15/AW15 -> -0.2203052 | BJ15: =BD15/AX15 -> 0.03035184 | BK15: =IFERROR(AM15/H15,0) -> 1 | BL15: =IFERROR(AN15/I15,0) -> 0.21092831 | BM15: =IFERROR(AO15/J15,0) -> 0.36435603 | BN15: =IFERROR(AP15/K15,0) -> 0.37468211 | BO15: =IFERROR(AQ15/L15,0) -> 0.28467007 | BP15: =IFERROR(AR15/M15,0) -> 0.32329386 | BQ15: =IFERROR(AS15/U15,0) -> 1 | BR15: =IFERROR(AT15/V15,0) -> 0.20765916 | BS15: =IFERROR(AU15/W15,0) -> 0.51032439 | BT15: =IFERROR(AV15/X15,0) -> 0.30375325 | BU15: =IFERROR(AW15/Y15,0) -> 0.26800126 | BV15: =IFERROR(AX15/Z15,0) -> 0.27902331 | BW15: =+BK15-BQ15 -> 0 | BX15: =+BL15-BR15 -> 0.0032691507 | BY15: =+BM15-BS15 -> -0.14596836 | BZ15: =+BN15-BT15 -> 0.070928866 | CA15: =+BO15-BU15 -> 0.016668809 | CB15: =+BP15-BV15 -> 0.044270549 | CC15: =BW15*10000 -> 0 | CD15: =BX15*10000 -> 32.691507 | CE15: =BY15*10000 -> -1459.6836 | CF15: =BZ15*10000 -> 709.28866 | CG15: =CA15*10000 -> 166.68809 | CH15: =CB15*10000 -> 442.70549
A16: FY26 | B16: FY25 | C16: 01 Jan | D16: 0 | E16: Week 01 | F16: =+F15+1 -> 46021 | G16: TUE | H16: 24.92 | I16: 20806.82 | J16: 1193.52 | K16: 67683.94 | L16: 72664.98 | M16: =SUM(H16:L16) -> 162374.18 | N16: FY25 | O16: FY24 | P16: 01 Jan | Q16: 0 | R16: Week 01 | S16: =+S15+1 -> 45657 | T16: TUE | U16: 129.89 | V16: 29934.01 | W16: 3777.71 | X16: 81720.47 | Y16: 76970.13 | Z16: =SUM(U16:Y16) -> 192532.21 | AA16: =+H16-U16 -> -104.97 | AB16: =+I16-V16 -> -9127.19 | AC16: =+J16-W16 -> -2584.19 | AD16: =+K16-X16 -> -14036.53 | AE16: =+L16-Y16 -> -4305.15 | AF16: =+M16-Z16 -> -30158.03 | AG16: =AA16/U16 -> -0.80814535 | AH16: =AB16/V16 -> -0.30491037 | AI16: =AC16/W16 -> -0.68406257 | AJ16: =AD16/X16 -> -0.17176272 | AK16: =AE16/Y16 -> -0.055932737 | AL16: =AF16/Z16 -> -0.15663888 | AM16: 24.92 | AN16: 4468.3 | AO16: 279 | AP16: 26740.28 | AQ16: 20601.89 | AR16: =SUM(AM16:AQ16) -> 52114.39 | AS16: 129.89 | AT16: 6286.86 | AU16: 1516.6 | AV16: 25541.08 | AW16: 21373.58 | AX16: =SUM(AS16:AW16) -> 54848.01 | AY16: =+AM16-AS16 -> -104.97 | AZ16: =+AN16-AT16 -> -1818.56 | BA16: =+AO16-AU16 -> -1237.6 | BB16: =+AP16-AV16 -> 1199.2 | BC16: =+AQ16-AW16 -> -771.69 | BD16: =+AR16-AX16 -> -2733.62 | BE16: =AY16/AS16 -> -0.80814535 | BF16: =AZ16/AT16 -> -0.28926364 | BG16: =BA16/AU16 -> -0.81603587 | BH16: =BB16/AV16 -> 0.046951813 | BI16: =BC16/AW16 -> -0.036104855 | BJ16: =BD16/AX16 -> -0.049839912 | BK16: =IFERROR(AM16/H16,0) -> 1 | BL16: =IFERROR(AN16/I16,0) -> 0.2147517 | BM16: =IFERROR(AO16/J16,0) -> 0.23376232 | BN16: =IFERROR(AP16/K16,0) -> 0.3950757 | BO16: =IFERROR(AQ16/L16,0) -> 0.28351883 | BP16: =IFERROR(AR16/M16,0) -> 0.32095244 | BQ16: =IFERROR(AS16/U16,0) -> 1 | BR16: =IFERROR(AT16/V16,0) -> 0.21002398 | BS16: =IFERROR(AU16/W16,0) -> 0.40146014 | BT16: =IFERROR(AV16/X16,0) -> 0.31254201 | BU16: =IFERROR(AW16/Y16,0) -> 0.27768668 | BV16: =IFERROR(AX16/Z16,0) -> 0.28487706 | BW16: =+BK16-BQ16 -> 0 | BX16: =+BL16-BR16 -> 0.0047277189 | BY16: =+BM16-BS16 -> -0.16769783 | BZ16: =+BN16-BT16 -> 0.08253369 | CA16: =+BO16-BU16 -> 0.0058321466 | CB16: =+BP16-BV16 -> 0.036075384 | CC16: =BW16*10000 -> 0 | CD16: =BX16*10000 -> 47.277189 | CE16: =BY16*10000 -> -1676.9783 | CF16: =BZ16*10000 -> 825.3369 | CG16: =CA16*10000 -> 58.321466 | CH16: =CB16*10000 -> 360.75384
A17: FY26 | B17: FY25 | C17: 01 Jan | D17: 0 | E17: Week 01 | F17: =+F16+1 -> 46022 | G17: WED | H17: 124.9 | I17: 31238.55 | J17: 3633.92 | K17: 105816.8 | L17: 86023.38 | M17: =SUM(H17:L17) -> 226837.55 | N17: FY25 | O17: FY25 | P17: 01 Jan | Q17: 01 Jan | R17: Week 01 | S17: =+S16+1 -> 45658 | T17: WED | U17: 24.98 | V17: 4839.75 | W17: 458.92 | X17: 11875.68 | Y17: 14952.65 | Z17: =SUM(U17:Y17) -> 32151.98 | AA17: =+H17-U17 -> 99.92 | AB17: =+I17-V17 -> 26398.8 | AC17: =+J17-W17 -> 3175 | AD17: =+K17-X17 -> 93941.12 | AE17: =+L17-Y17 -> 71070.73 | AF17: =+M17-Z17 -> 194685.57 | AG17: =AA17/U17 -> 4 | AH17: =AB17/V17 -> 5.4545793 | AI17: =AC17/W17 -> 6.9184172 | AJ17: =AD17/X17 -> 7.9103782 | AK17: =AE17/Y17 -> 4.7530525 | AL17: =AF17/Z17 -> 6.0551658 | AM17: 124.9 | AN17: 6802.78 | AO17: 1558.17 | AP17: 38677.41 | AQ17: 23133.82 | AR17: =SUM(AM17:AQ17) -> 70297.08 | AS17: 24.98 | AT17: 1017 | AU17: 139.67 | AV17: 3733.44 | AW17: 4105.75 | AX17: =SUM(AS17:AW17) -> 9020.84 | AY17: =+AM17-AS17 -> 99.92 | AZ17: =+AN17-AT17 -> 5785.78 | BA17: =+AO17-AU17 -> 1418.5 | BB17: =+AP17-AV17 -> 34943.97 | BC17: =+AQ17-AW17 -> 19028.07 | BD17: =+AR17-AX17 -> 61276.24 | BE17: =AY17/AS17 -> 4 | BF17: =AZ17/AT17 -> 5.6890659 | BG17: =BA17/AU17 -> 10.156082 | BH17: =BB17/AV17 -> 9.3597245 | BI17: =BC17/AW17 -> 4.6344931 | BJ17: =BD17/AX17 -> 6.7927421 | BK17: =IFERROR(AM17/H17,0) -> 1 | BL17: =IFERROR(AN17/I17,0) -> 0.21776875 | BM17: =IFERROR(AO17/J17,0) -> 0.42878489 | BN17: =IFERROR(AP17/K17,0) -> 0.36551294 | BO17: =IFERROR(AQ17/L17,0) -> 0.2689248 | BP17: =IFERROR(AR17/M17,0) -> 0.30990054 | BQ17: =IFERROR(AS17/U17,0) -> 1 | BR17: =IFERROR(AT17/V17,0) -> 0.21013482 | BS17: =IFERROR(AU17/W17,0) -> 0.30434498 | BT17: =IFERROR(AV17/X17,0) -> 0.31437695 | BU17: =IFERROR(AW17/Y17,0) -> 0.27458344 | BV17: =IFERROR(AX17/Z17,0) -> 0.28056872 | BW17: =+BK17-BQ17 -> 0 | BX17: =+BL17-BR17 -> 0.0076339295 | BY17: =+BM17-BS17 -> 0.12443991 | BZ17: =+BN17-BT17 -> 0.051135998 | CA17: =+BO17-BU17 -> -0.0056586381 | CB17: =+BP17-BV17 -> 0.029331819 | CC17: =BW17*10000 -> 0 | CD17: =BX17*10000 -> 76.339295 | CE17: =BY17*10000 -> 1244.3991 | CF17: =BZ17*10000 -> 511.35998 | CG17: =CA17*10000 -> -56.586381 | CH17: =CB17*10000 -> 293.31819
A18: FY26 | B18: FY26 | C18: 01 Jan | D18: 01 Jan | E18: Week 01 | F18: =+F17+1 -> 46023 | G18: THU | H18: 4.99 | I18: 5750.56 | J18: 491.07 | K18: 19093.48 | L18: 11260.64 | M18: =SUM(H18:L18) -> 36600.74 | N18: FY25 | O18: FY25 | P18: 01 Jan | Q18: 01 Jan | R18: Week 01 | S18: =+S17+1 -> 45659 | T18: THU | U18: 192.3 | V18: 9480.81 | W18: 209.78 | X18: 28581.7 | Y18: 28038.53 | Z18: =SUM(U18:Y18) -> 66503.12 | AA18: =+H18-U18 -> -187.31 | AB18: =+I18-V18 -> -3730.25 | AC18: =+J18-W18 -> 281.29 | AD18: =+K18-X18 -> -9488.22 | AE18: =+L18-Y18 -> -16777.89 | AF18: =+M18-Z18 -> -29902.38 | AG18: =AA18/U18 -> -0.97405096 | AH18: =AB18/V18 -> -0.39345267 | AI18: =AC18/W18 -> 1.3408809 | AJ18: =AD18/X18 -> -0.33196836 | AK18: =AE18/Y18 -> -0.59838693 | AL18: =AF18/Z18 -> -0.44963875 | AM18: 4.99 | AN18: 1259.38 | AO18: 111.95 | AP18: 8146.06 | AQ18: 3425 | AR18: =SUM(AM18:AQ18) -> 12947.38 | AS18: 192.3 | AT18: 1961.36 | AU18: -66.43 | AV18: 8640.53 | AW18: 7878.98 | AX18: =SUM(AS18:AW18) -> 18606.74 | AY18: =+AM18-AS18 -> -187.31 | AZ18: =+AN18-AT18 -> -701.98 | BA18: =+AO18-AU18 -> 178.38 | BB18: =+AP18-AV18 -> -494.47 | BC18: =+AQ18-AW18 -> -4453.98 | BD18: =+AR18-AX18 -> -5659.36 | BE18: =AY18/AS18 -> -0.97405096 | BF18: =AZ18/AT18 -> -0.35790472 | BG18: =BA18/AU18 -> -2.6852326 | BH18: =BB18/AV18 -> -0.057226814 | BI18: =BC18/AW18 -> -0.56529906 | BJ18: =BD18/AX18 -> -0.30415645 | BK18: =IFERROR(AM18/H18,0) -> 1 | BL18: =IFERROR(AN18/I18,0) -> 0.21900128 | BM18: =IFERROR(AO18/J18,0) -> 0.22797157 | BN18: =IFERROR(AP18/K18,0) -> 0.42664093 | BO18: =IFERROR(AQ18/L18,0) -> 0.30415678 | BP18: =IFERROR(AR18/M18,0) -> 0.3537464 | BQ18: =IFERROR(AS18/U18,0) -> 1 | BR18: =IFERROR(AT18/V18,0) -> 0.20687684 | BS18: =IFERROR(AU18/W18,0) -> -0.31666508 | BT18: =IFERROR(AV18/X18,0) -> 0.30230987 | BU18: =IFERROR(AW18/Y18,0) -> 0.28100546 | BV18: =IFERROR(AX18/Z18,0) -> 0.27978747 | BW18: =+BK18-BQ18 -> 0 | BX18: =+BL18-BR18 -> 0.012124441 | BY18: =+BM18-BS18 -> 0.54463665 | BZ18: =+BN18-BT18 -> 0.12433106 | CA18: =+BO18-BU18 -> 0.02315132 | CB18: =+BP18-BV18 -> 0.073958925 | CC18: =BW18*10000 -> 0 | CD18: =BX18*10000 -> 121.24441 | CE18: =BY18*10000 -> 5446.3665 | CF18: =BZ18*10000 -> 1243.3106 | CG18: =CA18*10000 -> 231.5132 | CH18: =CB18*10000 -> 739.58925
A19: FY26 | B19: FY26 | C19: 01 Jan | D19: 01 Jan | E19: Week 01 | F19: =+F18+1 -> 46024 | G19: FRI | H19: 14.94 | I19: 14765.96 | J19: 751.98 | K19: 37203.9 | L19: 38268.11 | M19: =SUM(H19:L19) -> 91004.89 | N19: FY25 | O19: FY25 | P19: 01 Jan | Q19: 01 Jan | R19: Week 01 | S19: =+S18+1 -> 45660 | T19: FRI | U19: 88.65 | V19: 13720.3 | W19: 568.09 | X19: 36597.8 | Y19: 32608.07 | Z19: =SUM(U19:Y19) -> 83582.91 | AA19: =+H19-U19 -> -73.71 | AB19: =+I19-V19 -> 1045.66 | AC19: =+J19-W19 -> 183.89 | AD19: =+K19-X19 -> 606.1 | AE19: =+L19-Y19 -> 5660.04 | AF19: =+M19-Z19 -> 7421.98 | AG19: =AA19/U19 -> -0.83147208 | AH19: =AB19/V19 -> 0.076212619 | AI19: =AC19/W19 -> 0.32369871 | AJ19: =AD19/X19 -> 0.016561105 | AK19: =AE19/Y19 -> 0.17357789 | AL19: =AF19/Z19 -> 0.088797818 | AM19: 14.94 | AN19: 2994.72 | AO19: 225.75 | AP19: 12831.74 | AQ19: 10195.42 | AR19: =SUM(AM19:AQ19) -> 26262.57 | AS19: 88.65 | AT19: 2775.74 | AU19: 185.01 | AV19: 11206.38 | AW19: 9322.27 | AX19: =SUM(AS19:AW19) -> 23578.05 | AY19: =+AM19-AS19 -> -73.71 | AZ19: =+AN19-AT19 -> 218.98 | BA19: =+AO19-AU19 -> 40.74 | BB19: =+AP19-AV19 -> 1625.36 | BC19: =+AQ19-AW19 -> 873.15 | BD19: =+AR19-AX19 -> 2684.52 | BE19: =AY19/AS19 -> -0.83147208 | BF19: =AZ19/AT19 -> 0.078890674 | BG19: =BA19/AU19 -> 0.22020431 | BH19: =BB19/AV19 -> 0.14503881 | BI19: =BC19/AW19 -> 0.09366281 | BJ19: =BD19/AX19 -> 0.11385674 | BK19: =IFERROR(AM19/H19,0) -> 1 | BL19: =IFERROR(AN19/I19,0) -> 0.20281241 | BM19: =IFERROR(AO19/J19,0) -> 0.30020745 | BN19: =IFERROR(AP19/K19,0) -> 0.34490309 | BO19: =IFERROR(AQ19/L19,0) -> 0.26642079 | BP19: =IFERROR(AR19/M19,0) -> 0.28858416 | BQ19: =IFERROR(AS19/U19,0) -> 1 | BR19: =IFERROR(AT19/V19,0) -> 0.20230899 | BS19: =IFERROR(AU19/W19,0) -> 0.32567023 | BT19: =IFERROR(AV19/X19,0) -> 0.30620365 | BU19: =IFERROR(AW19/Y19,0) -> 0.28588843 | BV19: =IFERROR(AX19/Z19,0) -> 0.28209176 | BW19: =+BK19-BQ19 -> 0 | BX19: =+BL19-BR19 -> 0.00050342709 | BY19: =+BM19-BS19 -> -0.025462776 | BZ19: =+BN19-BT19 -> 0.038699437 | CA19: =+BO19-BU19 -> -0.019467644 | CB19: =+BP19-BV19 -> 0.0064924051 | CC19: =BW19*10000 -> 0 | CD19: =BX19*10000 -> 5.0342709 | CE19: =BY19*10000 -> -254.62776 | CF19: =BZ19*10000 -> 386.99437 | CG19: =CA19*10000 -> -194.67644 | CH19: =CB19*10000 -> 64.924051
A20: FY26 | B20: FY26 | C20: 01 Jan | D20: 01 Jan | E20: Week 01 | F20: =+F19+1 -> 46025 | G20: SAT | H20: 139.93 | I20: 11588.21 | J20: 828.77 | K20: 34231.15 | L20: 27048.09 | M20: =SUM(H20:L20) -> 73836.15 | N20: FY25 | O20: FY25 | P20: 01 Jan | Q20: 01 Jan | R20: Week 01 | S20: =+S19+1 -> 45661 | T20: SAT | U20: 29.97 | V20: 14372.62 | W20: 180.81 | X20: 35136.33 | Y20: 32994.35 | Z20: =SUM(U20:Y20) -> 82714.08 | AA20: =+H20-U20 -> 109.96 | AB20: =+I20-V20 -> -2784.41 | AC20: =+J20-W20 -> 647.96 | AD20: =+K20-X20 -> -905.18 | AE20: =+L20-Y20 -> -5946.26 | AF20: =+M20-Z20 -> -8877.93 | AG20: =AA20/U20 -> 3.6690023 | AH20: =AB20/V20 -> -0.19373016 | AI20: =AC20/W20 -> 3.5836513 | AJ20: =AD20/X20 -> -0.025761939 | AK20: =AE20/Y20 -> -0.18022055 | AL20: =AF20/Z20 -> -0.10733275 | AM20: 139.93 | AN20: 2516.07 | AO20: 300.85 | AP20: 11414.8 | AQ20: 8038.63 | AR20: =SUM(AM20:AQ20) -> 22410.28 | AS20: 29.97 | AT20: 3098.51 | AU20: -95.62 | AV20: 10879.63 | AW20: 9633.63 | AX20: =SUM(AS20:AW20) -> 23546.12 | AY20: =+AM20-AS20 -> 109.96 | AZ20: =+AN20-AT20 -> -582.44 | BA20: =+AO20-AU20 -> 396.47 | BB20: =+AP20-AV20 -> 535.17 | BC20: =+AQ20-AW20 -> -1595 | BD20: =+AR20-AX20 -> -1135.84 | BE20: =AY20/AS20 -> 3.6690023 | BF20: =AZ20/AT20 -> -0.18797422 | BG20: =BA20/AU20 -> -4.1463083 | BH20: =BB20/AV20 -> 0.049190092 | BI20: =BC20/AW20 -> -0.16556584 | BJ20: =BD20/AX20 -> -0.048238946 | BK20: =IFERROR(AM20/H20,0) -> 1 | BL20: =IFERROR(AN20/I20,0) -> 0.21712327 | BM20: =IFERROR(AO20/J20,0) -> 0.36300783 | BN20: =IFERROR(AP20/K20,0) -> 0.33346236 | BO20: =IFERROR(AQ20/L20,0) -> 0.29719769 | BP20: =IFERROR(AR20/M20,0) -> 0.30351366 | BQ20: =IFERROR(AS20/U20,0) -> 1 | BR20: =IFERROR(AT20/V20,0) -> 0.21558421 | BS20: =IFERROR(AU20/W20,0) -> -0.52884243 | BT20: =IFERROR(AV20/X20,0) -> 0.30964048 | BU20: =IFERROR(AW20/Y20,0) -> 0.29197817 | BV20: =IFERROR(AX20/Z20,0) -> 0.28466883 | BW20: =+BK20-BQ20 -> 0 | BX20: =+BL20-BR20 -> 0.0015390508 | BY20: =+BM20-BS20 -> 0.89185026 | BZ20: =+BN20-BT20 -> 0.023821881 | CA20: =+BO20-BU20 -> 0.0052195229 | CB20: =+BP20-BV20 -> 0.018844833 | CC20: =BW20*10000 -> 0 | CD20: =BX20*10000 -> 15.390508 | CE20: =BY20*10000 -> 8918.5026 | CF20: =BZ20*10000 -> 238.21881 | CG20: =CA20*10000 -> 52.195229 | CH20: =CB20*10000 -> 188.44833
A21: FY26 | B21: FY26 | C21: 01 Jan | D21: 01 Jan | E21: Week 02 | F21: =+F20+1 -> 46026 | G21: SUN | H21: 29.97 | I21: 7651.58 | J21: 223.07 | K21: 19386.4 | L21: 17174.12 | M21: =SUM(H21:L21) -> 44465.14 | N21: FY25 | O21: FY25 | P21: 01 Jan | Q21: 01 Jan | R21: Week 02 | S21: =+S20+1 -> 45662 | T21: SUN | U21: 49.93 | V21: 7387.57 | W21: 460.86 | X21: 23207.13 | Y21: 16401.54 | Z21: =SUM(U21:Y21) -> 47507.03 | AA21: =+H21-U21 -> -19.96 | AB21: =+I21-V21 -> 264.01 | AC21: =+J21-W21 -> -237.79 | AD21: =+K21-X21 -> -3820.73 | AE21: =+L21-Y21 -> 772.58 | AF21: =+M21-Z21 -> -3041.89 | AG21: =AA21/U21 -> -0.39975966 | AH21: =AB21/V21 -> 0.035737056 | AI21: =AC21/W21 -> -0.51597014 | AJ21: =AD21/X21 -> -0.16463604 | AK21: =AE21/Y21 -> 0.047104113 | AL21: =AF21/Z21 -> -0.064030313 | AM21: 29.97 | AN21: 1641.77 | AO21: 50.56 | AP21: 6262.15 | AQ21: 4951.11 | AR21: =SUM(AM21:AQ21) -> 12935.56 | AS21: 49.93 | AT21: 1566.49 | AU21: 111.13 | AV21: 7349.26 | AW21: 4707.66 | AX21: =SUM(AS21:AW21) -> 13784.47 | AY21: =+AM21-AS21 -> -19.96 | AZ21: =+AN21-AT21 -> 75.28 | BA21: =+AO21-AU21 -> -60.57 | BB21: =+AP21-AV21 -> -1087.11 | BC21: =+AQ21-AW21 -> 243.45 | BD21: =+AR21-AX21 -> -848.91 | BE21: =AY21/AS21 -> -0.39975966 | BF21: =AZ21/AT21 -> 0.048056483 | BG21: =BA21/AU21 -> -0.54503734 | BH21: =BB21/AV21 -> -0.14792102 | BI21: =BC21/AW21 -> 0.05171359 | BJ21: =BD21/AX21 -> -0.061584522 | BK21: =IFERROR(AM21/H21,0) -> 1 | BL21: =IFERROR(AN21/I21,0) -> 0.21456614 | BM21: =IFERROR(AO21/J21,0) -> 0.22665531 | BN21: =IFERROR(AP21/K21,0) -> 0.32301768 | BO21: =IFERROR(AQ21/L21,0) -> 0.28828901 | BP21: =IFERROR(AR21/M21,0) -> 0.29091464 | BQ21: =IFERROR(AS21/U21,0) -> 1 | BR21: =IFERROR(AT21/V21,0) -> 0.21204401 | BS21: =IFERROR(AU21/W21,0) -> 0.24113614 | BT21: =IFERROR(AV21/X21,0) -> 0.31668112 | BU21: =IFERROR(AW21/Y21,0) -> 0.28702549 | BV21: =IFERROR(AX21/Z21,0) -> 0.29015643 | BW21: =+BK21-BQ21 -> 0 | BX21: =+BL21-BR21 -> 0.0025221274 | BY21: =+BM21-BS21 -> -0.014480827 | BZ21: =+BN21-BT21 -> 0.0063365591 | CA21: =+BO21-BU21 -> 0.0012635203 | CB21: =+BP21-BV21 -> 0.00075821033 | CC21: =BW21*10000 -> 0 | CD21: =BX21*10000 -> 25.221274 | CE21: =BY21*10000 -> -144.80827 | CF21: =BZ21*10000 -> 63.365591 | CG21: =CA21*10000 -> 12.635203 | CH21: =CB21*10000 -> 7.5821033
A22: FY26 | B22: FY26 | C22: 01 Jan | D22: 01 Jan | E22: Week 02 | F22: =+F21+1 -> 46027 | G22: MON | H22: 85.33 | I22: 7593.79 | J22: 358.09 | K22: 23720.96 | L22: 23403.82 | M22: =SUM(H22:L22) -> 55161.99 | N22: FY25 | O22: FY25 | P22: 01 Jan | Q22: 01 Jan | R22: Week 02 | S22: =+S21+1 -> 45663 | T22: MON | U22: 224.85 | V22: 8156.35 | W22: 514.13 | X22: 33307.07 | Y22: 32807.79 | Z22: =SUM(U22:Y22) -> 75010.19 | AA22: =+H22-U22 -> -139.52 | AB22: =+I22-V22 -> -562.56 | AC22: =+J22-W22 -> -156.04 | AD22: =+K22-X22 -> -9586.11 | AE22: =+L22-Y22 -> -9403.97 | AF22: =+M22-Z22 -> -19848.2 | AG22: =AA22/U22 -> -0.62050256 | AH22: =AB22/V22 -> -0.068972028 | AI22: =AC22/W22 -> -0.30350301 | AJ22: =AD22/X22 -> -0.28781007 | AK22: =AE22/Y22 -> -0.28663833 | AL22: =AF22/Z22 -> -0.26460672 | AM22: 85.33 | AN22: 1578.31 | AO22: 77.76 | AP22: 7700.8 | AQ22: 6956.31 | AR22: =SUM(AM22:AQ22) -> 16398.51 | AS22: 224.85 | AT22: 1594.3 | AU22: 218.94 | AV22: 10130.4 | AW22: 9014.1 | AX22: =SUM(AS22:AW22) -> 21182.59 | AY22: =+AM22-AS22 -> -139.52 | AZ22: =+AN22-AT22 -> -15.99 | BA22: =+AO22-AU22 -> -141.18 | BB22: =+AP22-AV22 -> -2429.6 | BC22: =+AQ22-AW22 -> -2057.79 | BD22: =+AR22-AX22 -> -4784.08 | BE22: =AY22/AS22 -> -0.62050256 | BF22: =AZ22/AT22 -> -0.01002948 | BG22: =BA22/AU22 -> -0.6448342 | BH22: =BB22/AV22 -> -0.23983258 | BI22: =BC22/AW22 -> -0.22828569 | BJ22: =BD22/AX22 -> -0.22584962 | BK22: =IFERROR(AM22/H22,0) -> 1 | BL22: =IFERROR(AN22/I22,0) -> 0.2078422 | BM22: =IFERROR(AO22/J22,0) -> 0.21715211 | BN22: =IFERROR(AP22/K22,0) -> 0.32464116 | BO22: =IFERROR(AQ22/L22,0) -> 0.29722968 | BP22: =IFERROR(AR22/M22,0) -> 0.29727916 | BQ22: =IFERROR(AS22/U22,0) -> 1 | BR22: =IFERROR(AT22/V22,0) -> 0.19546734 | BS22: =IFERROR(AU22/W22,0) -> 0.4258456 | BT22: =IFERROR(AV22/X22,0) -> 0.30415164 | BU22: =IFERROR(AW22/Y22,0) -> 0.27475487 | BV22: =IFERROR(AX22/Z22,0) -> 0.28239617 | BW22: =+BK22-BQ22 -> 0 | BX22: =+BL22-BR22 -> 0.012374862 | BY22: =+BM22-BS22 -> -0.20869349 | BZ22: =+BN22-BT22 -> 0.02048952 | CA22: =+BO22-BU22 -> 0.022474815 | CB22: =+BP22-BV22 -> 0.014882994 | CC22: =BW22*10000 -> 0 | CD22: =BX22*10000 -> 123.74862 | CE22: =BY22*10000 -> -2086.9349 | CF22: =BZ22*10000 -> 204.8952 | CG22: =CA22*10000 -> 224.74815 | CH22: =CB22*10000 -> 148.82994
A23: FY26 | B23: FY26 | C23: 01 Jan | D23: 01 Jan | E23: Week 02 | F23: =+F22+1 -> 46028 | G23: TUE | H23: 24.95 | I23: 7734.18 | J23: 368.37 | K23: 28623.92 | L23: 22686.61 | M23: =SUM(H23:L23) -> 59438.03 | N23: FY25 | O23: FY25 | P23: 01 Jan | Q23: 01 Jan | R23: Week 02 | S23: =+S22+1 -> 45664 | T23: TUE | U23: 49.93 | V23: 7037.43 | W23: 240.4 | X23: 23269.05 | Y23: 20585.9 | Z23: =SUM(U23:Y23) -> 51182.71 | AA23: =+H23-U23 -> -24.98 | AB23: =+I23-V23 -> 696.75 | AC23: =+J23-W23 -> 127.97 | AD23: =+K23-X23 -> 5354.87 | AE23: =+L23-Y23 -> 2100.71 | AF23: =+M23-Z23 -> 8255.32 | AG23: =AA23/U23 -> -0.50030042 | AH23: =AB23/V23 -> 0.099006313 | AI23: =AC23/W23 -> 0.53232113 | AJ23: =AD23/X23 -> 0.23012843 | AK23: =AE23/Y23 -> 0.10204606 | AL23: =AF23/Z23 -> 0.16129119 | AM23: 24.95 | AN23: 1561.99 | AO23: 110.31 | AP23: 10601.75 | AQ23: 7092.67 | AR23: =SUM(AM23:AQ23) -> 19391.67 | AS23: 49.93 | AT23: 1459.36 | AU23: 88.1 | AV23: 9456.19 | AW23: 5087.9 | AX23: =SUM(AS23:AW23) -> 16141.48 | AY23: =+AM23-AS23 -> -24.98 | AZ23: =+AN23-AT23 -> 102.63 | BA23: =+AO23-AU23 -> 22.21 | BB23: =+AP23-AV23 -> 1145.56 | BC23: =+AQ23-AW23 -> 2004.77 | BD23: =+AR23-AX23 -> 3250.19 | BE23: =AY23/AS23 -> -0.50030042 | BF23: =AZ23/AT23 -> 0.070325348 | BG23: =BA23/AU23 -> 0.25209989 | BH23: =BB23/AV23 -> 0.12114393 | BI23: =BC23/AW23 -> 0.39402701 | BJ23: =BD23/AX23 -> 0.20135638 | BK23: =IFERROR(AM23/H23,0) -> 1 | BL23: =IFERROR(AN23/I23,0) -> 0.20195935 | BM23: =IFERROR(AO23/J23,0) -> 0.29945435 | BN23: =IFERROR(AP23/K23,0) -> 0.37038079 | BO23: =IFERROR(AQ23/L23,0) -> 0.31263684 | BP23: =IFERROR(AR23/M23,0) -> 0.32625021 | BQ23: =IFERROR(AS23/U23,0) -> 1 | BR23: =IFERROR(AT23/V23,0) -> 0.20737116 | BS23: =IFERROR(AU23/W23,0) -> 0.36647255 | BT23: =IFERROR(AV23/X23,0) -> 0.40638488 | BU23: =IFERROR(AW23/Y23,0) -> 0.24715461 | BV23: =IFERROR(AX23/Z23,0) -> 0.31536978 | BW23: =+BK23-BQ23 -> 0 | BX23: =+BL23-BR23 -> -0.0054118024 | BY23: =+BM23-BS23 -> -0.067018193 | BZ23: =+BN23-BT23 -> -0.03600409 | CA23: =+BO23-BU23 -> 0.065482232 | CB23: =+BP23-BV23 -> 0.010880434 | CC23: =BW23*10000 -> 0 | CD23: =BX23*10000 -> -54.118024 | CE23: =BY23*10000 -> -670.18193 | CF23: =BZ23*10000 -> -360.0409 | CG23: =CA23*10000 -> 654.82232 | CH23: =CB23*10000 -> 108.80434
A24: FY26 | B24: FY26 | C24: 01 Jan | D24: 01 Jan | E24: Week 02 | F24: =+F23+1 -> 46029 | G24: WED | H24: 74.94 | I24: 11294.36 | J24: 620.16 | K24: 47284.79 | L24: 55953.33 | M24: =SUM(H24:L24) -> 115227.58 | N24: FY25 | O24: FY25 | P24: 01 Jan | Q24: 01 Jan | R24: Week 02 | S24: =+S23+1 -> 45665 | T24: WED | U24: 69.51 | V24: 10062.54 | W24: 545.08 | X24: 33892.12 | Y24: 35393.37 | Z24: =SUM(U24:Y24) -> 79962.62 | AA24: =+H24-U24 -> 5.43 | AB24: =+I24-V24 -> 1231.82 | AC24: =+J24-W24 -> 75.08 | AD24: =+K24-X24 -> 13392.67 | AE24: =+L24-Y24 -> 20559.96 | AF24: =+M24-Z24 -> 35264.96 | AG24: =AA24/U24 -> 0.078118256 | AH24: =AB24/V24 -> 0.12241641 | AI24: =AC24/W24 -> 0.13774125 | AJ24: =AD24/X24 -> 0.39515587 | AK24: =AE24/Y24 -> 0.58089863 | AL24: =AF24/Z24 -> 0.44101807 | AM24: 74.94 | AN24: 2305.7 | AO24: 59.32 | AP24: 23708.37 | AQ24: 13505.36 | AR24: =SUM(AM24:AQ24) -> 39653.69 | AS24: 69.51 | AT24: 1933.2 | AU24: 144.21 | AV24: 11671.6 | AW24: 9775.26 | AX24: =SUM(AS24:AW24) -> 23593.78 | AY24: =+AM24-AS24 -> 5.43 | AZ24: =+AN24-AT24 -> 372.5 | BA24: =+AO24-AU24 -> -84.89 | BB24: =+AP24-AV24 -> 12036.77 | BC24: =+AQ24-AW24 -> 3730.1 | BD24: =+AR24-AX24 -> 16059.91 | BE24: =AY24/AS24 -> 0.078118256 | BF24: =AZ24/AT24 -> 0.1926857 | BG24: =BA24/AU24 -> -0.58865543 | BH24: =BB24/AV24 -> 1.0312871 | BI24: =BC24/AW24 -> 0.38158576 | BJ24: =BD24/AX24 -> 0.68068406 | BK24: =IFERROR(AM24/H24,0) -> 1 | BL24: =IFERROR(AN24/I24,0) -> 0.20414614 | BM24: =IFERROR(AO24/J24,0) -> 0.095652735 | BN24: =IFERROR(AP24/K24,0) -> 0.50139527 | BO24: =IFERROR(AQ24/L24,0) -> 0.2413683 | BP24: =IFERROR(AR24/M24,0) -> 0.34413367 | BQ24: =IFERROR(AS24/U24,0) -> 1 | BR24: =IFERROR(AT24/V24,0) -> 0.19211849 | BS24: =IFERROR(AU24/W24,0) -> 0.26456667 | BT24: =IFERROR(AV24/X24,0) -> 0.34437503 | BU24: =IFERROR(AW24/Y24,0) -> 0.27618902 | BV24: =IFERROR(AX24/Z24,0) -> 0.29506012 | BW24: =+BK24-BQ24 -> 0 | BX24: =+BL24-BR24 -> 0.012027649 | BY24: =+BM24-BS24 -> -0.16891393 | BZ24: =+BN24-BT24 -> 0.15702023 | CA24: =+BO24-BU24 -> -0.034820718 | CB24: =+BP24-BV24 -> 0.049073553 | CC24: =BW24*10000 -> 0 | CD24: =BX24*10000 -> 120.27649 | CE24: =BY24*10000 -> -1689.1393 | CF24: =BZ24*10000 -> 1570.2023 | CG24: =CA24*10000 -> -348.20718 | CH24: =CB24*10000 -> 490.73553
A25: FY26 | B25: FY26 | C25: 01 Jan | D25: 01 Jan | E25: Week 02 | F25: =+F24+1 -> 46030 | G25: THU | H25: 184.87 | I25: 10152.49 | J25: 287.05 | K25: 39927.03 | L25: 36799.69 | M25: =SUM(H25:L25) -> 87351.13 | N25: FY25 | O25: FY25 | P25: 01 Jan | Q25: 01 Jan | R25: Week 02 | S25: =+S24+1 -> 45666 | T25: THU | U25: 187.65 | V25: 11592.09 | W25: 621.27 | X25: 31064.78 | Y25: 23769.04 | Z25: =SUM(U25:Y25) -> 67234.83 | AA25: =+H25-U25 -> -2.78 | AB25: =+I25-V25 -> -1439.6 | AC25: =+J25-W25 -> -334.22 | AD25: =+K25-X25 -> 8862.25 | AE25: =+L25-Y25 -> 13030.65 | AF25: =+M25-Z25 -> 20116.3 | AG25: =AA25/U25 -> -0.014814815 | AH25: =AB25/V25 -> -0.12418813 | AI25: =AC25/W25 -> -0.53796256 | AJ25: =AD25/X25 -> 0.28528288 | AK25: =AE25/Y25 -> 0.54821945 | AL25: =AF25/Z25 -> 0.29919463 | AM25: 144.15 | AN25: 2155.58 | AO25: 68.3 | AP25: 16125.33 | AQ25: 9842.55 | AR25: =SUM(AM25:AQ25) -> 28335.91 | AS25: 187.65 | AT25: 2355.72 | AU25: 269.43 | AV25: 10625.82 | AW25: 6628.73 | AX25: =SUM(AS25:AW25) -> 20067.35 | AY25: =+AM25-AS25 -> -43.5 | AZ25: =+AN25-AT25 -> -200.14 | BA25: =+AO25-AU25 -> -201.13 | BB25: =+AP25-AV25 -> 5499.51 | BC25: =+AQ25-AW25 -> 3213.82 | BD25: =+AR25-AX25 -> 8268.56 | BE25: =AY25/AS25 -> -0.23181455 | BF25: =AZ25/AT25 -> -0.084959163 | BG25: =BA25/AU25 -> -0.74650187 | BH25: =BB25/AV25 -> 0.517561 | BI25: =BC25/AW25 -> 0.48483194 | BJ25: =BD25/AX25 -> 0.41204045 | BK25: =IFERROR(AM25/H25,0) -> 0.77973711 | BL25: =IFERROR(AN25/I25,0) -> 0.21232033 | BM25: =IFERROR(AO25/J25,0) -> 0.23793764 | BN25: =IFERROR(AP25/K25,0) -> 0.40387001 | BO25: =IFERROR(AQ25/L25,0) -> 0.26746285 | BP25: =IFERROR(AR25/M25,0) -> 0.32439088 | BQ25: =IFERROR(AS25/U25,0) -> 1 | BR25: =IFERROR(AT25/V25,0) -> 0.20321788 | BS25: =IFERROR(AU25/W25,0) -> 0.43367618 | BT25: =IFERROR(AV25/X25,0) -> 0.34205361 | BU25: =IFERROR(AW25/Y25,0) -> 0.27888085 | BV25: =IFERROR(AX25/Z25,0) -> 0.29846658 | BW25: =+BK25-BQ25 -> -0.22026289 | BX25: =+BL25-BR25 -> 0.0091024434 | BY25: =+BM25-BS25 -> -0.19573854 | BZ25: =+BN25-BT25 -> 0.061816404 | CA25: =+BO25-BU25 -> -0.011417996 | CB25: =+BP25-BV25 -> 0.025924297 | CC25: =BW25*10000 -> -2202.6289 | CD25: =BX25*10000 -> 91.024434 | CE25: =BY25*10000 -> -1957.3854 | CF25: =BZ25*10000 -> 618.16404 | CG25: =CA25*10000 -> -114.17996 | CH25: =CB25*10000 -> 259.24297
A26: FY26 | B26: FY26 | C26: 01 Jan | D26: 01 Jan | E26: Week 02 | F26: =+F25+1 -> 46031 | G26: FRI | H26: 99.92 | I26: 15830.92 | J26: 849.08 | K26: 47706.02 | L26: 34191.19 | M26: =SUM(H26:L26) -> 98677.13 | N26: FY25 | O26: FY25 | P26: 01 Jan | Q26: 01 Jan | R26: Week 02 | S26: =+S25+1 -> 45667 | T26: FRI | U26: 54.95 | V26: 20185.48 | W26: 874.47 | X26: 50966.88 | Y26: 40374.41 | Z26: =SUM(U26:Y26) -> 112456.19 | AA26: =+H26-U26 -> 44.97 | AB26: =+I26-V26 -> -4354.56 | AC26: =+J26-W26 -> -25.39 | AD26: =+K26-X26 -> -3260.86 | AE26: =+L26-Y26 -> -6183.22 | AF26: =+M26-Z26 -> -13779.06 | AG26: =AA26/U26 -> 0.81838035 | AH26: =AB26/V26 -> -0.21572734 | AI26: =AC26/W26 -> -0.02903473 | AJ26: =AD26/X26 -> -0.063979981 | AK26: =AE26/Y26 -> -0.15314701 | AL26: =AF26/Z26 -> -0.12252825 | AM26: 99.92 | AN26: 3356.38 | AO26: 269.02 | AP26: 17777.38 | AQ26: 9953.67 | AR26: =SUM(AM26:AQ26) -> 31456.37 | AS26: 54.95 | AT26: 4169.47 | AU26: 318.7 | AV26: 15973.98 | AW26: 11494.96 | AX26: =SUM(AS26:AW26) -> 32012.06 | AY26: =+AM26-AS26 -> 44.97 | AZ26: =+AN26-AT26 -> -813.09 | BA26: =+AO26-AU26 -> -49.68 | BB26: =+AP26-AV26 -> 1803.4 | BC26: =+AQ26-AW26 -> -1541.29 | BD26: =+AR26-AX26 -> -555.69 | BE26: =AY26/AS26 -> 0.81838035 | BF26: =AZ26/AT26 -> -0.1950104 | BG26: =BA26/AU26 -> -0.15588328 | BH26: =BB26/AV26 -> 0.1128961 | BI26: =BC26/AW26 -> -0.13408398 | BJ26: =BD26/AX26 -> -0.01735877 | BK26: =IFERROR(AM26/H26,0) -> 1 | BL26: =IFERROR(AN26/I26,0) -> 0.21201421 | BM26: =IFERROR(AO26/J26,0) -> 0.31683705 | BN26: =IFERROR(AP26/K26,0) -> 0.37264437 | BO26: =IFERROR(AQ26/L26,0) -> 0.29111798 | BP26: =IFERROR(AR26/M26,0) -> 0.31878075 | BQ26: =IFERROR(AS26/U26,0) -> 1 | BR26: =IFERROR(AT26/V26,0) -> 0.20655788 | BS26: =IFERROR(AU26/W26,0) -> 0.36444932 | BT26: =IFERROR(AV26/X26,0) -> 0.31341883 | BU26: =IFERROR(AW26/Y26,0) -> 0.28470905 | BV26: =IFERROR(AX26/Z26,0) -> 0.2846625 | BW26: =+BK26-BQ26 -> 0 | BX26: =+BL26-BR26 -> 0.005456328 | BY26: =+BM26-BS26 -> -0.047612276 | BZ26: =+BN26-BT26 -> 0.059225543 | CA26: =+BO26-BU26 -> 0.006408923 | CB26: =+BP26-BV26 -> 0.034118257 | CC26: =BW26*10000 -> 0 | CD26: =BX26*10000 -> 54.56328 | CE26: =BY26*10000 -> -476.12276 | CF26: =BZ26*10000 -> 592.25543 | CG26: =CA26*10000 -> 64.08923 | CH26: =CB26*10000 -> 341.18257
A27: FY26 | B27: FY26 | C27: 01 Jan | D27: 01 Jan | E27: Week 02 | F27: =+F26+1 -> 46032 | G27: SAT | H27: 19.99 | I27: 15874.33 | J27: 1237.38 | K27: 46804.32 | L27: 36021.04 | M27: =SUM(H27:L27) -> 99957.06 | N27: FY25 | O27: FY25 | P27: 01 Jan | Q27: 01 Jan | R27: Week 02 | S27: =+S26+1 -> 45668 | T27: SAT | U27: 19.99 | V27: 16468.49 | W27: 1126.15 | X27: 45912.94 | Y27: 37324.43 | Z27: =SUM(U27:Y27) -> 100852 | AA27: =+H27-U27 -> 0 | AB27: =+I27-V27 -> -594.16 | AC27: =+J27-W27 -> 111.23 | AD27: =+K27-X27 -> 891.38 | AE27: =+L27-Y27 -> -1303.39 | AF27: =+M27-Z27 -> -894.94 | AG27: =AA27/U27 -> 0 | AH27: =AB27/V27 -> -0.036078596 | AI27: =AC27/W27 -> 0.098770146 | AJ27: =AD27/X27 -> 0.01941457 | AK27: =AE27/Y27 -> -0.03492056 | AL27: =AF27/Z27 -> -0.0088737953 | AM27: 19.99 | AN27: 3442.68 | AO27: 398.16 | AP27: 16489.53 | AQ27: 11207.4 | AR27: =SUM(AM27:AQ27) -> 31557.76 | AS27: 19.99 | AT27: 3481.84 | AU27: 480.03 | AV27: 14325.72 | AW27: 10696.79 | AX27: =SUM(AS27:AW27) -> 29004.37 | AY27: =+AM27-AS27 -> 0 | AZ27: =+AN27-AT27 -> -39.16 | BA27: =+AO27-AU27 -> -81.87 | BB27: =+AP27-AV27 -> 2163.81 | BC27: =+AQ27-AW27 -> 510.61 | BD27: =+AR27-AX27 -> 2553.39 | BE27: =AY27/AS27 -> 0 | BF27: =AZ27/AT27 -> -0.011246927 | BG27: =BA27/AU27 -> -0.17055184 | BH27: =BB27/AV27 -> 0.15104372 | BI27: =BC27/AW27 -> 0.047734881 | BJ27: =BD27/AX27 -> 0.088034665 | BK27: =IFERROR(AM27/H27,0) -> 1 | BL27: =IFERROR(AN27/I27,0) -> 0.21687089 | BM27: =IFERROR(AO27/J27,0) -> 0.32177666 | BN27: =IFERROR(AP27/K27,0) -> 0.35230786 | BO27: =IFERROR(AQ27/L27,0) -> 0.31113483 | BP27: =IFERROR(AR27/M27,0) -> 0.31571317 | BQ27: =IFERROR(AS27/U27,0) -> 1 | BR27: =IFERROR(AT27/V27,0) -> 0.21142436 | BS27: =IFERROR(AU27/W27,0) -> 0.4262576 | BT27: =IFERROR(AV27/X27,0) -> 0.31201923 | BU27: =IFERROR(AW27/Y27,0) -> 0.28658951 | BV27: =IFERROR(AX27/Z27,0) -> 0.2875934 | BW27: =+BK27-BQ27 -> 0 | BX27: =+BL27-BR27 -> 0.0054465227 | BY27: =+BM27-BS27 -> -0.10448095 | BZ27: =+BN27-BT27 -> 0.040288638 | CA27: =+BO27-BU27 -> 0.024545318 | CB27: =+BP27-BV27 -> 0.028119763 | CC27: =BW27*10000 -> 0 | CD27: =BX27*10000 -> 54.465227 | CE27: =BY27*10000 -> -1044.8095 | CF27: =BZ27*10000 -> 402.88638 | CG27: =CA27*10000 -> 245.45318 | CH27: =CB27*10000 -> 281.19763
A28: FY26 | B28: FY26 | C28: 01 Jan | D28: 01 Jan | E28: Week 03 | F28: =+F27+1 -> 46033 | G28: SUN | H28: 24.95 | I28: 8758.29 | J28: 129.15 | K28: 27069.94 | L28: 20775.26 | M28: =SUM(H28:L28) -> 56757.59 | N28: FY25 | O28: FY25 | P28: 01 Jan | Q28: 01 Jan | R28: Week 03 | S28: =+S27+1 -> 45669 | T28: SUN | U28: 24.95 | V28: 8755.71 | W28: 510.83 | X28: 22354.98 | Y28: 20673.72 | Z28: =SUM(U28:Y28) -> 52320.19 | AA28: =+H28-U28 -> 0 | AB28: =+I28-V28 -> 2.58 | AC28: =+J28-W28 -> -381.68 | AD28: =+K28-X28 -> 4714.96 | AE28: =+L28-Y28 -> 101.54 | AF28: =+M28-Z28 -> 4437.4 | AG28: =AA28/U28 -> 0 | AH28: =AB28/V28 -> 0.00029466485 | AI28: =AC28/W28 -> -0.74717616 | AJ28: =AD28/X28 -> 0.21091318 | AK28: =AE28/Y28 -> 0.0049115495 | AL28: =AF28/Z28 -> 0.084812383 | AM28: 24.95 | AN28: 1889.95 | AO28: -13.44 | AP28: 9327.68 | AQ28: 6661.22 | AR28: =SUM(AM28:AQ28) -> 17890.36 | AS28: 24.95 | AT28: 1811.63 | AU28: 139.57 | AV28: 6703.71 | AW28: 5931.34 | AX28: =SUM(AS28:AW28) -> 14611.2 | AY28: =+AM28-AS28 -> 0 | AZ28: =+AN28-AT28 -> 78.32 | BA28: =+AO28-AU28 -> -153.01 | BB28: =+AP28-AV28 -> 2623.97 | BC28: =+AQ28-AW28 -> 729.88 | BD28: =+AR28-AX28 -> 3279.16 | BE28: =AY28/AS28 -> 0 | BF28: =AZ28/AT28 -> 0.043231786 | BG28: =BA28/AU28 -> -1.0962958 | BH28: =BB28/AV28 -> 0.39142057 | BI28: =BC28/AW28 -> 0.12305482 | BJ28: =BD28/AX28 -> 0.22442784 | BK28: =IFERROR(AM28/H28,0) -> 1 | BL28: =IFERROR(AN28/I28,0) -> 0.21578984 | BM28: =IFERROR(AO28/J28,0) -> -0.10406504 | BN28: =IFERROR(AP28/K28,0) -> 0.34457705 | BO28: =IFERROR(AQ28/L28,0) -> 0.32063233 | BP28: =IFERROR(AR28/M28,0) -> 0.31520648 | BQ28: =IFERROR(AS28/U28,0) -> 1 | BR28: =IFERROR(AT28/V28,0) -> 0.20690841 | BS28: =IFERROR(AU28/W28,0) -> 0.27322201 | BT28: =IFERROR(AV28/X28,0) -> 0.29987546 | BU28: =IFERROR(AW28/Y28,0) -> 0.28690241 | BV28: =IFERROR(AX28/Z28,0) -> 0.27926504 | BW28: =+BK28-BQ28 -> 0 | BX28: =+BL28-BR28 -> 0.0088814342 | BY28: =+BM28-BS28 -> -0.37728705 | BZ28: =+BN28-BT28 -> 0.044701583 | CA28: =+BO28-BU28 -> 0.033729923 | CB28: =+BP28-BV28 -> 0.035941436 | CC28: =BW28*10000 -> 0 | CD28: =BX28*10000 -> 88.814342 | CE28: =BY28*10000 -> -3772.8705 | CF28: =BZ28*10000 -> 447.01583 | CG28: =CA28*10000 -> 337.29923 | CH28: =CB28*10000 -> 359.41436
A29: FY26 | B29: FY26 | C29: 01 Jan | D29: 01 Jan | E29: Week 03 | F29: =+F28+1 -> 46034 | G29: MON | H29: 104.88 | I29: 7266.19 | J29: 253.35 | K29: 33525.95 | L29: 26672.64 | M29: =SUM(H29:L29) -> 67823.01 | N29: FY25 | O29: FY25 | P29: 01 Jan | Q29: 01 Jan | R29: Week 03 | S29: =+S28+1 -> 45670 | T29: MON | U29: 88.8 | V29: 7946.83 | W29: 343.64 | X29: 31174.73 | Y29: 25655.52 | Z29: =SUM(U29:Y29) -> 65209.52 | AA29: =+H29-U29 -> 16.08 | AB29: =+I29-V29 -> -680.64 | AC29: =+J29-W29 -> -90.29 | AD29: =+K29-X29 -> 2351.22 | AE29: =+L29-Y29 -> 1017.12 | AF29: =+M29-Z29 -> 2613.49 | AG29: =AA29/U29 -> 0.18108108 | AH29: =AB29/V29 -> -0.085649246 | AI29: =AC29/W29 -> -0.2627459 | AJ29: =AD29/X29 -> 0.075420701 | AK29: =AE29/Y29 -> 0.039645269 | AL29: =AF29/Z29 -> 0.040078351 | AM29: 104.88 | AN29: 1481.09 | AO29: 72.03 | AP29: 13575.63 | AQ29: 7948.86 | AR29: =SUM(AM29:AQ29) -> 23182.49 | AS29: 88.8 | AT29: 1588.35 | AU29: 234.99 | AV29: 9716.88 | AW29: 7415.05 | AX29: =SUM(AS29:AW29) -> 19044.07 | AY29: =+AM29-AS29 -> 16.08 | AZ29: =+AN29-AT29 -> -107.26 | BA29: =+AO29-AU29 -> -162.96 | BB29: =+AP29-AV29 -> 3858.75 | BC29: =+AQ29-AW29 -> 533.81 | BD29: =+AR29-AX29 -> 4138.42 | BE29: =AY29/AS29 -> 0.18108108 | BF29: =AZ29/AT29 -> -0.067529197 | BG29: =BA29/AU29 -> -0.69347632 | BH29: =BB29/AV29 -> 0.39711821 | BI29: =BC29/AW29 -> 0.071990074 | BJ29: =BD29/AX29 -> 0.21730754 | BK29: =IFERROR(AM29/H29,0) -> 1 | BL29: =IFERROR(AN29/I29,0) -> 0.2038331 | BM29: =IFERROR(AO29/J29,0) -> 0.28431024 | BN29: =IFERROR(AP29/K29,0) -> 0.40492902 | BO29: =IFERROR(AQ29/L29,0) -> 0.29801549 | BP29: =IFERROR(AR29/M29,0) -> 0.34180863 | BQ29: =IFERROR(AS29/U29,0) -> 1 | BR29: =IFERROR(AT29/V29,0) -> 0.19987215 | BS29: =IFERROR(AU29/W29,0) -> 0.6838261 | BT29: =IFERROR(AV29/X29,0) -> 0.31169091 | BU29: =IFERROR(AW29/Y29,0) -> 0.28902357 | BV29: =IFERROR(AX29/Z29,0) -> 0.29204432 | BW29: =+BK29-BQ29 -> 0 | BX29: =+BL29-BR29 -> 0.0039609452 | BY29: =+BM29-BS29 -> -0.39951585 | BZ29: =+BN29-BT29 -> 0.093238106 | CA29: =+BO29-BU29 -> 0.0089919238 | CB29: =+BP29-BV29 -> 0.049764307 | CC29: =BW29*10000 -> 0 | CD29: =BX29*10000 -> 39.609452 | CE29: =BY29*10000 -> -3995.1585 | CF29: =BZ29*10000 -> 932.38106 | CG29: =CA29*10000 -> 89.919238 | CH29: =CB29*10000 -> 497.64307
... A377: FY26 | B377: FY26 | C377: 12 Dec | D377: 12 Dec | E377: Week 52 | F377: =+F376+1 -> 46382 | G377: SAT | H377: 0 | I377: 0 | J377: 0 | K377: 0 | L377: 0 | M377: =SUM(H377:L377) -> 0 | N377: FY25 | O377: FY25 | P377: 12 Dec | Q377: 12 Dec | R377: Week 52 | S377: =+S376+1 -> 46018 | T377: SAT | U377: 104.94 | V377: 14188 | W377: 881.04 | X377: 53531.92 | Y377: 42451.05 | Z377: =SUM(U377:Y377) -> 111156.95 | AA377: =+H377-U377 -> -104.94 | AB377: =+I377-V377 -> -14188 | AC377: =+J377-W377 -> -881.04 | AD377: =+K377-X377 -> -53531.92 | AE377: =+L377-Y377 -> -42451.05 | AF377: =+M377-Z377 -> -111156.95 | AG377: =AA377/U377 -> -1 | AH377: =AB377/V377 -> -1 | AI377: =AC377/W377 -> -1 | AJ377: =AD377/X377 -> -1 | AK377: =AE377/Y377 -> -1 | AL377: =AF377/Z377 -> -1 | AM377: 0 | AN377: 0 | AO377: 0 | AP377: 0 | AQ377: 0 | AR377: =SUM(AM377:AQ377) -> 0 | AS377: 104.94 | AT377: 3045.13 | AU377: 271.7 | AV377: 20911.64 | AW377: 12838.41 | AX377: =SUM(AS377:AW377) -> 37171.82 | AY377: =+AM377-AS377 -> -104.94 | AZ377: =+AN377-AT377 -> -3045.13 | BA377: =+AO377-AU377 -> -271.7 | BB377: =+AP377-AV377 -> -20911.64 | BC377: =+AQ377-AW377 -> -12838.41 | BD377: =+AR377-AX377 -> -37171.82 | BE377: =AY377/AS377 -> -1 | BF377: =AZ377/AT377 -> -1 | BG377: =BA377/AU377 -> -1 | BH377: =BB377/AV377 -> -1 | BI377: =BC377/AW377 -> -1 | BJ377: =BD377/AX377 -> -1 | BK377: =IFERROR(AM377/H377,0) -> 0 | BL377: =IFERROR(AN377/I377,0) -> 0 | BM377: =IFERROR(AO377/J377,0) -> 0 | BN377: =IFERROR(AP377/K377,0) -> 0 | BO377: =IFERROR(AQ377/L377,0) -> 0 | BP377: =IFERROR(AR377/M377,0) -> 0 | BQ377: =IFERROR(AS377/U377,0) -> 1 | BR377: =IFERROR(AT377/V377,0) -> 0.21462715 | BS377: =IFERROR(AU377/W377,0) -> 0.30838554 | BT377: =IFERROR(AV377/X377,0) -> 0.39063871 | BU377: =IFERROR(AW377/Y377,0) -> 0.30242856 | BV377: =IFERROR(AX377/Z377,0) -> 0.33440842 | BW377: =+BK377-BQ377 -> -1 | BX377: =+BL377-BR377 -> -0.21462715 | BY377: =+BM377-BS377 -> -0.30838554 | BZ377: =+BN377-BT377 -> -0.39063871 | CA377: =+BO377-BU377 -> -0.30242856 | CB377: =+BP377-BV377 -> -0.33440842 | CC377: =BW377*10000 -> -10000 | CD377: =BX377*10000 -> -2146.2715 | CE377: =BY377*10000 -> -3083.8554 | CF377: =BZ377*10000 -> -3906.3871 | CG377: =CA377*10000 -> -3024.2856 | CH377: =CB377*10000 -> -3344.0842
F379: Week 01 | H379: =SUMIF($E$14:$E$377,$F379,H$14:H$377) -> 379.6 | I379: =SUMIF($E$14:$E$377,$F379,I$14:I$377) -> 103959.65 | J379: =SUMIF($E$14:$E$377,$F379,J$14:J$377) -> 8578.44 | K379: =SUMIF($E$14:$E$377,$F379,K$14:K$377) -> 358569.47 | L379: =SUMIF($E$14:$E$377,$F379,L$14:L$377) -> 296274.72 | M379: =SUM(H379:L379) -> 767761.88 | T379: Week 01 | U379: =SUMIF($M$14:$M$20,"<>0",U$14:U$20) -> 530.72 | V379: =SUMIF($M$14:$M$20,"<>0",V$14:V$20) -> 98608.03 | W379: =SUMIF($M$14:$M$20,"<>0",W$14:W$20) -> 7686.29 | X379: =SUMIF($M$14:$M$20,"<>0",X$14:X$20) -> 279903.57 | Y379: =SUMIF($M$14:$M$20,"<>0",Y$14:Y$20) -> 267353.87 | Z379: =SUM(U379:Y379) -> 654082.48 | AA379: =+H379-U379 -> -151.12 | AB379: =+I379-V379 -> 5351.62 | AC379: =+J379-W379 -> 892.15 | AD379: =+K379-X379 -> 78665.9 | AE379: =+L379-Y379 -> 28920.85 | AF379: =+M379-Z379 -> 113679.4 | AG379: =IFERROR(AA379/U379,"") -> -0.28474525 | AH379: =IFERROR(AB379/V379,"") -> 0.054271645 | AI379: =IFERROR(AC379/W379,"") -> 0.1160703 | AJ379: =IFERROR(AD379/X379,"") -> 0.28104643 | AK379: =IFERROR(AE379/Y379,"") -> 0.10817442 | AL379: =IFERROR(AF379/Z379,"") -> 0.17379979 | AM379: =SUMIF($E$14:$E$377,$F379,AM$14:AM$377) -> 379.6 | AN379: =SUMIF($E$14:$E$377,$F379,AN$14:AN$377) -> 22297.97 | AO379: =SUMIF($E$14:$E$377,$F379,AO$14:AO$377) -> 3120.56 | AP379: =SUMIF($E$14:$E$377,$F379,AP$14:AP$377) -> 136529.92 | AQ379: =SUMIF($E$14:$E$377,$F379,AQ$14:AQ$377) -> 83050.87 | AR379: =SUM(AM379:AQ379) -> 245378.92 | AS379: =SUMIF($M$14:$M$20,"<>0",AS$14:AS$20) -> 530.72 | AT379: =SUMIF($M$14:$M$20,"<>0",AT$14:AT$20) -> 20663.19 | AU379: =SUMIF($M$14:$M$20,"<>0",AU$14:AU$20) -> 2896.27 | AV379: =SUMIF($M$14:$M$20,"<>0",AV$14:AV$20) -> 85502.77 | AW379: =SUMIF($M$14:$M$20,"<>0",AW$14:AW$20) -> 74484.19 | AX379: =SUM(AS379:AW379) -> 184077.14 | AY379: =+AM379-AS379 -> -151.12 | AZ379: =+AN379-AT379 -> 1634.78 | BA379: =+AO379-AU379 -> 224.29 | BB379: =+AP379-AV379 -> 51027.15 | BC379: =+AQ379-AW379 -> 8566.68 | BD379: =+AR379-AX379 -> 61301.78 | BE379: =AY379/AS379 -> -0.28474525 | BF379: =AZ379/AT379 -> 0.079115567 | BG379: =BA379/AU379 -> 0.077440984 | BH379: =BB379/AV379 -> 0.59678944 | BI379: =BC379/AW379 -> 0.1150134 | BJ379: =BD379/AX379 -> 0.33302223 | BK379: =IFERROR(AM379/H379,0) -> 1 | BL379: =IFERROR(AN379/I379,0) -> 0.21448677 | BM379: =IFERROR(AO379/J379,0) -> 0.36376777 | BN379: =IFERROR(AP379/K379,0) -> 0.38076281 | BO379: =IFERROR(AQ379/L379,0) -> 0.2803171 | BP379: =IFERROR(AR379/M379,0) -> 0.3196029 | BQ379: =IFERROR(AS379/U379,0) -> 1 | BR379: =IFERROR(AT379/V379,0) -> 0.20954876 | BS379: =IFERROR(AU379/W379,0) -> 0.37680988 | BT379: =IFERROR(AV379/X379,0) -> 0.30547224 | BU379: =IFERROR(AW379/Y379,0) -> 0.27859776 | BV379: =IFERROR(AX379/Z379,0) -> 0.28142802 | BW379: =+BK379-BQ379 -> 0 | BX379: =+BL379-BR379 -> 0.0049380186 | BY379: =+BM379-BS379 -> -0.013042107 | BZ379: =+BN379-BT379 -> 0.075290575 | CA379: =+BO379-BU379 -> 0.0017193364 | CB379: =+BP379-BV379 -> 0.038174871 | CC379: =BW379*10000 -> 0 | CD379: =BX379*10000 -> 49.380186 | CE379: =BY379*10000 -> -130.42107 | CF379: =BZ379*10000 -> 752.90575 | CG379: =CA379*10000 -> 17.193364 | CH379: =CB379*10000 -> 381.74871
